[2025-08-19 16:08:44.712152] Error loading user: (1129, "Host '172.31.39.42' is blocked because of many connection errors; unblock with 'mysqladmin flush-hosts'")
Traceback (most recent call last):
  File "C:\Users\VTGS_LAP_01\OneDrive - VIOLIN TECHNOLOGIES PRIVATE LIMITED\Desktop\CMS_Pro\venv_cms\Lib\site-packages\flask\app.py", line 917, in full_dispatch_request
    rv = self.dispatch_request()
  File "C:\Users\VTGS_LAP_01\OneDrive - VIOLIN TECHNOLOGIES PRIVATE LIMITED\Desktop\CMS_Pro\venv_cms\Lib\site-packages\flask\app.py", line 891, in dispatch_request
    self.raise_routing_exception(req)
    ~~~~~~~~~~~~~~~~~~~~~~~~~~~~^^^^^
  File "C:\Users\VTGS_LAP_01\OneDrive - VIOLIN TECHNOLOGIES PRIVATE LIMITED\Desktop\CMS_Pro\venv_cms\Lib\site-packages\flask\app.py", line 500, in raise_routing_exception
    raise request.routing_exception  # type: ignore[misc]
    ^^^^^^^^^^^^^^^^^^^^^^^^^^^^^^^
  File "C:\Users\VTGS_LAP_01\OneDrive - VIOLIN TECHNOLOGIES PRIVATE LIMITED\Desktop\CMS_Pro\venv_cms\Lib\site-packages\flask\ctx.py", line 362, in match_request
    result = self.url_adapter.match(return_rule=True)  # type: ignore
  File "C:\Users\VTGS_LAP_01\OneDrive - VIOLIN TECHNOLOGIES PRIVATE LIMITED\Desktop\CMS_Pro\venv_cms\Lib\site-packages\werkzeug\routing\map.py", line 629, in match
    raise NotFound() from None
werkzeug.exceptions.NotFound: 404 Not Found: The requested URL was not found on the server. If you entered the URL manually please check your spelling and try again.

During handling of the above exception, another exception occurred:

Traceback (most recent call last):
  File "C:\Users\VTGS_LAP_01\OneDrive - VIOLIN TECHNOLOGIES PRIVATE LIMITED\Desktop\CMS_Pro\app\__init__.py", line 32, in load_user
    cur = mysql.connection.cursor()
          ^^^^^^^^^^^^^^^^
  File "C:\Users\VTGS_LAP_01\OneDrive - VIOLIN TECHNOLOGIES PRIVATE LIMITED\Desktop\CMS_Pro\venv_cms\Lib\site-packages\flask_mysqldb\__init__.py", line 109, in connection
    ctx.mysql_db = self.connect
                   ^^^^^^^^^^^^
  File "C:\Users\VTGS_LAP_01\OneDrive - VIOLIN TECHNOLOGIES PRIVATE LIMITED\Desktop\CMS_Pro\venv_cms\Lib\site-packages\flask_mysqldb\__init__.py", line 97, in connect
    return MySQLdb.connect(**kwargs)
           ~~~~~~~~~~~~~~~^^^^^^^^^^
  File "C:\Users\VTGS_LAP_01\OneDrive - VIOLIN TECHNOLOGIES PRIVATE LIMITED\Desktop\CMS_Pro\venv_cms\Lib\site-packages\MySQLdb\__init__.py", line 121, in Connect
    return Connection(*args, **kwargs)
  File "C:\Users\VTGS_LAP_01\OneDrive - VIOLIN TECHNOLOGIES PRIVATE LIMITED\Desktop\CMS_Pro\venv_cms\Lib\site-packages\MySQLdb\connections.py", line 200, in __init__
    super().__init__(*args, **kwargs2)
    ~~~~~~~~~~~~~~~~^^^^^^^^^^^^^^^^^^
MySQLdb.OperationalError: (1129, "Host '172.31.39.42' is blocked because of many connection errors; unblock with 'mysqladmin flush-hosts'")
[2025-08-19 16:10:41.790045] Error loading user: (1129, "Host '172.31.39.42' is blocked because of many connection errors; unblock with 'mysqladmin flush-hosts'")
Traceback (most recent call last):
  File "C:\Users\VTGS_LAP_01\OneDrive - VIOLIN TECHNOLOGIES PRIVATE LIMITED\Desktop\CMS_Pro\venv_cms\Lib\site-packages\flask\app.py", line 917, in full_dispatch_request
    rv = self.dispatch_request()
  File "C:\Users\VTGS_LAP_01\OneDrive - VIOLIN TECHNOLOGIES PRIVATE LIMITED\Desktop\CMS_Pro\venv_cms\Lib\site-packages\flask\app.py", line 891, in dispatch_request
    self.raise_routing_exception(req)
    ~~~~~~~~~~~~~~~~~~~~~~~~~~~~^^^^^
  File "C:\Users\VTGS_LAP_01\OneDrive - VIOLIN TECHNOLOGIES PRIVATE LIMITED\Desktop\CMS_Pro\venv_cms\Lib\site-packages\flask\app.py", line 500, in raise_routing_exception
    raise request.routing_exception  # type: ignore[misc]
    ^^^^^^^^^^^^^^^^^^^^^^^^^^^^^^^
  File "C:\Users\VTGS_LAP_01\OneDrive - VIOLIN TECHNOLOGIES PRIVATE LIMITED\Desktop\CMS_Pro\venv_cms\Lib\site-packages\flask\ctx.py", line 362, in match_request
    result = self.url_adapter.match(return_rule=True)  # type: ignore
  File "C:\Users\VTGS_LAP_01\OneDrive - VIOLIN TECHNOLOGIES PRIVATE LIMITED\Desktop\CMS_Pro\venv_cms\Lib\site-packages\werkzeug\routing\map.py", line 629, in match
    raise NotFound() from None
werkzeug.exceptions.NotFound: 404 Not Found: The requested URL was not found on the server. If you entered the URL manually please check your spelling and try again.

During handling of the above exception, another exception occurred:

Traceback (most recent call last):
  File "C:\Users\VTGS_LAP_01\OneDrive - VIOLIN TECHNOLOGIES PRIVATE LIMITED\Desktop\CMS_Pro\app\__init__.py", line 32, in load_user
    cur = mysql.connection.cursor()
          ^^^^^^^^^^^^^^^^
  File "C:\Users\VTGS_LAP_01\OneDrive - VIOLIN TECHNOLOGIES PRIVATE LIMITED\Desktop\CMS_Pro\venv_cms\Lib\site-packages\flask_mysqldb\__init__.py", line 109, in connection
    ctx.mysql_db = self.connect
                   ^^^^^^^^^^^^
  File "C:\Users\VTGS_LAP_01\OneDrive - VIOLIN TECHNOLOGIES PRIVATE LIMITED\Desktop\CMS_Pro\venv_cms\Lib\site-packages\flask_mysqldb\__init__.py", line 97, in connect
    return MySQLdb.connect(**kwargs)
           ~~~~~~~~~~~~~~~^^^^^^^^^^
  File "C:\Users\VTGS_LAP_01\OneDrive - VIOLIN TECHNOLOGIES PRIVATE LIMITED\Desktop\CMS_Pro\venv_cms\Lib\site-packages\MySQLdb\__init__.py", line 121, in Connect
    return Connection(*args, **kwargs)
  File "C:\Users\VTGS_LAP_01\OneDrive - VIOLIN TECHNOLOGIES PRIVATE LIMITED\Desktop\CMS_Pro\venv_cms\Lib\site-packages\MySQLdb\connections.py", line 200, in __init__
    super().__init__(*args, **kwargs2)
    ~~~~~~~~~~~~~~~~^^^^^^^^^^^^^^^^^^
MySQLdb.OperationalError: (1129, "Host '172.31.39.42' is blocked because of many connection errors; unblock with 'mysqladmin flush-hosts'")
